Workbook

Sheet TORQUE TARGET CALCS
A1: REFERENCE | B1: https://evwest.com/support/PMxxx%20Datasheet%2001052012.pdf | E1: *YOU WANT TO DESIGN AROUND TORQUE NOT CURRENT AS TORQUE CASUES SHEAR, POWER RESULTS IN HIGHER SPEED
A2: REFERENCE | B2: EMRAX_208_datasheet_v1.6.pdf | C2: *IN GOOGLE DRIVE | E2: *ASSUMES EMRAX 208 MV
B4: PEAK TORQUE | J4: EMRAX 208 HV (MECHANICAL METHOD) | L4: continuous
I5: operating speed | K5: HIGH | L5: MEDIUM | M5: LOW
B6: Bus Voltage | C6: 300 | J6: Average Vehicle Speed [AVS] (mph) | K6: 60 | L6: 30 | M6: 15
B7: Motor Voltage | C7: =C6/SQRT(2) -> 212.13203 | J7: Average Vehicle Speed [AVS] (m/s) | K7: =K6*0.44704 -> 26.8224 | L7: =L6*0.44704 -> 13.4112 | M7: =M6*0.44704 -> 6.7056
B8: Peak Current (Arms) | C8: 283 | D8: Peak current from 2026 cells | I8: Hoosier 16.0X7.5-10 R20 | J8: Wheel Diameter (m) | K8: =(16/12)*(0.3048) -> 0.4064 | L8: =(16/12)*(0.3048) -> 0.4064 | M8: =(16/12)*(0.3048) -> 0.4064
B9: K_T Constant (N*m/Arms) | C9: 0.38 | I9: This would be the large sprocket angular velocity | J9: Average Vehicle Angular Speed (rad/s) | K9: =K7/(K8/2) -> 132 | L9: =L7/(L8/2) -> 66 | M9: =M7/(M8/2) -> 33
B10: Peak Torque (N*m) | C10: =C8*C9 -> 107.54 | J10: Gear Ratio | K10: 4.7 | L10: 4.7 | M10: 4.7
I11: Small sprocket on the motor, so higher speed | J11: Motor Speed (rad/s) | K11: =K9*K10 -> 620.4 | L11: =L9*L10 -> 310.2 | M11: =M9*M10 -> 155.1
B12: CONTINUOUS TORQUE | C12: *for fatigue analsysis | J12: Average RPM | K12: =K11*60/(2*PI()) -> 5924.3836 | L12: =L11*60/(2*PI()) -> 2962.1918 | M12: =M11*60/(2*PI()) -> 1481.0959

Sheet ASSUMPTIONS
B1: *Standard used: ISO 606; cross referenced with motorcyle chain standard | G1: * For HIGH, MEDIUM, LOW, consider the different event you want to design for
B2: ASSUMPTIONS
A3: operating speed | C3: HIGH | D3: MEDIUM | E3: LOW
B4: Torque [M] | C4: ='TORQUE TARGET CALCS'!C10 -> 107.54 | D4: ='TORQUE TARGET CALCS'!C10 -> 107.54 | E4: ='TORQUE TARGET CALCS'!C10 -> 107.54
A5: input | B5: Rotational Speed Motor [n_1] (rpm) | C5: ='TORQUE TARGET CALCS'!K12 -> 5924.3836 | D5: ='TORQUE TARGET CALCS'!L12 -> 2962.1918 | E5: ='TORQUE TARGET CALCS'!M12 -> 1481.0959 | F5: *small sprocket speed
B6: Driven Sprocket Speed [n_2] (rpm) | C6: =C5/CALCULATIONS!C5 -> 1260.5071 | D6: =D5/CALCULATIONS!D5 -> 630.25357 | E6: =E5/CALCULATIONS!E5 -> 315.12679 | F6: *rotational speed of the large driven sprocket
A7: input | B7: Teeth Small Sprocket [z_1] | C7: 10 | D7: 10 | E7: 10 | F7: *4.7 Gear Ratio
A8: input | B8: Teeth Large Sprocket [z_2] | C8: 47 | D8: 47 | E8: 47
A9: input | B9: Dynamic Overload [f_1] | C9: 2 | D9: 2 | E9: 2
A10: input | B10: Gear Ratio Factor [f_2] | C10: 0.97 | D10: 0.97 | E10: 0.97 | F10: *from IWIS
A11: input | B11: Dynamic Shock Factor [f_3] | C11: 1.37 | D11: 1.37 | E11: 1.37
A12: input | B12: Center Distance Factor (a/p) [f_4] | C12: 1.26 | D12: 1.26 | E12: 1.26 | F12: *a/p needed, from IWIS | G12: ='SPROCKET GEOMETRY'!K51/'SPROCKET GEOMETRY'!J4 -> 16.71254
A13: input | B13: Lubrication Factor [f_5] | C13: 1 | D13: 1 | E13: 1
B14: Multi-Shaft Drive Factor [f_6] | C14: 1 | D14: 1 | E14: 1
B15: Influencing Factor [f_G] | C15: =C9*C10*C11*C12*C13*C14 -> 3.348828 | D15: =D9*D10*D11*D12*D13*D14 -> 3.348828 | E15: =E9*E10*E11*E12*E13*E14 -> 3.348828

Sheet CHAIN SELECTION
B3: Operating Speed | C3: HIGH | D3: MEDIUM | E3: LOW
B4: Power Transmitted [P] (kW) | C4: =ASSUMPTIONS!C4*ASSUMPTIONS!C5/9550 -> 66.712902 | D4: =ASSUMPTIONS!D4*ASSUMPTIONS!D5/9550 -> 33.356451 | E4: =ASSUMPTIONS!E4*ASSUMPTIONS!E5/9550 -> 16.678225
B5: Corrected Power [P_D] (kW) | C5: =C4*ASSUMPTIONS!C15 -> 223.41003 | D5: =D4*ASSUMPTIONS!D15 -> 111.70502 | E5: =E4*ASSUMPTIONS!E15 -> 55.852508 | T5: This graph and table are ISO standard way to pick chain which we can't use b/c of exessive power and RPM but it is a good reference of what not to do
T6: The table this is an example of the motorcycle chain size tables, motorcycle chains are standarized and can be cross referenced to ISO sprockets standards
B7: POINT ON ISO 10823 GRAPH
AC8: REFERENCE
B9: Corrected Power [P_D] (kW) | C9: =C5 -> 223.41003 | D9: =D5 -> 111.70502 | E9: =E5 -> 55.852508
B10: Rotational Speed [RPM] | C10: =ASSUMPTIONS!C5 -> 5924.3836 | D10: =ASSUMPTIONS!D5 -> 2962.1918 | E10: =ASSUMPTIONS!E5 -> 1481.0959
B11: Total Working Tension [F_G] (N) | C11: =CALCULATIONS!C24 -> 5357.1558 | D11: =CALCULATIONS!D24 -> 5264.2914 | E11: =CALCULATIONS!E24 -> 5241.0753
B12: Selected Standard | C12: 428 | D12: 428 | E12: 428
A13: *from datasheet | B13: Chain Tensile Strength (lb) | C13: 6400 | D13: 6400 | E13: 6400 | U13: https://cdn.standards.iteh.ai/samples/1787/04627b58b4b94ae5b072512340264062/ISO-10823-1996.pdf
B14: Chain Tensile Strength (N) | C14: =C13*4.4482 -> 28468.48 | D14: =D13*4.4482 -> 28468.48 | E14: =E13*4.4482 -> 28468.48
B15: Safety Factor AER 27 | C15: =C14/C11 -> 5.3141034 | D15: =D14/D11 -> 5.4078465 | E15: =E14/E11 -> 5.4318013
B17: Safety Factor AER 26 | C17: =23486/5120 -> 4.5871094 | D17: N/A | E17: N/A
C18: *under 105 Nm torque and 6500 rpm
B19: *Google ISO equivalent to chosen motorcycle chain
A21: *cross reference | B21: CHAIN PROPERTIES MOTORCYCLE CHAIN
A23: input | B23: Chain Pitch [p] (mm) | C23: 12.7 | D23: 12.7 | E23: 12.7
A24: input | B24: Roller Diameter [d_r] (mm) | C24: 8.51 | D24: 8.51 | E24: 8.51
A25: input | B25: Inner Width [b_z] (mm) | C25: 7.2 | D25: 7.2 | E25: 7.2
A26: input | B26: Mass Per Unit Length [q] (kg/m] | C26: =1/(1.27) -> 0.78740157 | D26: =1/(1.27) -> 0.78740157 | E26: =1/(1.27) -> 0.78740157 | F26: *pitch= 12.7, length 100 links = 127mm = .127m
A27: input | B27: Weight Per Link [q_l] (kg/link) | C27: =1/100 -> 0.01 | D27: =1/100 -> 0.01 | E27: =1/100 -> 0.01 | H27: https://www.ebay.com/itm/358625822454?chn=ps&norover=1&mkevt=1&mkrid=711-117182-37290-0&mkcid=2&mkscid=101&itemid=358625822454&targetid=2315428266900&device=c&mktype=pla&googleloc=9058844&poi=&campaignid=21394550841&mkgroupid=173029507588&rlsatarget=pla-2315428266900&abcId=9448521&merchantid=5711626535&gad_source=1&gad_campaignid=21394550841&gclid=CjwKCAjw1IHTBhAaEiwA4AYNFjepemkfZjpKSmfUALbTCC68bwkXAWMp1D4visNb174eiG2kRYgShBoCjRkQAvD_BwE
A28: input | B28: Young's Modulus [E] (N/mm^2) | C28: 200000 | D28: 200000 | E28: 200000 | F28: *Young's modulus for steel | H28: AER 26 | I28: AER 27
G29: Chain | H29: RK 428MXU (Ultra-Thin U-Ring) | I29: RK 428XSO (RX-Ring / X-Ring)
G30: Seal Type | H30: U-Ring (50% thinner than standard seals) | I30: RX-Ring (Dual-lip X-ring profile)
G31: Maintenance Need | H31: Low (Internal factory grease is sealed in) | I31: Very Low (Maximum seal durability for long runs)
G32: Weight (per 100 Links) | H32: 1.00 kg | I32: 1.20 kg
G33: Friction / Drag | H33: Ultra-Low (Micro-contact points reduce seal drag) | I33: Moderate (Standard RX-Ring wiping drag)
G34: Tensile Strength (UTS) (lb) | H34: 6400 | I34: 5280
G35: Cost Per Link | H35: =150/120 -> 1.25 | I35: =95/130 -> 0.73076923

Sheet SPROCKET GEOMETRY
B1: *STANDARD USED: ISO 606; THIS STANDARD COMPROMISES OF ANSI AND BRITISH | J1: SPROCKET CAD TUTORIAL: https://www.chiefdelphi.com/t/sprocket-design-tutorial/387449
B2: *SPECIFIC STANDARD USED: ANSI
I3: CHAIN PROPERTIES SMALL SPROCKET | N3: CHAIN PROPERTIES LARGE SPROCKET
I4: Chain Pitch [p] (mm) | J4: ='CHAIN SELECTION'!C23 -> 12.7 | N4: Chain Pitch [p] (mm) | O4: =J4 -> 12.7
I5: Chain Pitch [p] (in) | J5: =J4*0.03937 -> 0.499999 | N5: Chain Pitch [p] (in) | O5: =O4*0.03937 -> 0.499999
I6: Roller Diameter [D_r] (mm) | J6: ='CHAIN SELECTION'!C24 -> 8.51 | N6: Roller Diameter [D_r] (mm) | O6: =J6 -> 8.51 | Q6: angle of pressure is gamma and comes from CAD
I7: Roller Diameter [D_r] (in) | J7: =J6*0.03937 -> 0.3350387 | N7: Roller Diameter [D_r] (in) | O7: =O6*0.03937 -> 0.3350387
I8: Inner Width (mm) | J8: ='CHAIN SELECTION'!C25 -> 7.2 | N8: Inner Width [b_z] (mm) | O8: =J8 -> 7.2
I9: Number Teeth | J9: 10 | N9: Number Teeth | O9: 47
I10: Pitch Circle[d] (mm) | J10: =J4/(SIN(RADIANS(180/J9))) -> 41.098063 | N10: Pitch Circle [d] (mm) | O10: =O4/(SIN(RADIANS(180/O9))) -> 190.14073
I11: Pitch Circle (in) | J11: =0.03937*J10 -> 1.6180308 | N11: Pitch Circle (in) | O11: =O10*0.03937 -> 7.4858405
I12: d_R = d_1 | J12: =J6 -> 8.51 | K12: *w/ tolerance of +0.01 mm | N12: d_R = d_1 | O12: =O6 -> 8.51 | P12: *w/ tolerance of +0.01 mm
I13: Root Diam. [d_f] | J13: =J10-J12 -> 32.588063 | K13: *w/ tolerance of -0.25mm | N13: Root Diam. [d_f] | O13: =O10-O12 -> 181.63073 | P13: *w/ tolerance of -0.30mm
I14: M_R | J14: =J10+J12 -> 49.608063 | N14: M_R | O14: =O10*COS(RADIANS(90/O9))+O12 -> 198.54455
I15: r_e_max | J15: =0.12*J12*(J9+2) -> 12.2544 | N15: r_e_max | O15: =0.12*O12*(O9+2) -> 50.0388
I16: r_i_min | J16: =0.505*J12 -> 4.29755 | N16: r_i_min | O16: =0.505*O12 -> 4.29755
I17: alpha_max | J17: =140-90/J9 -> 131 | N17: alpha_max | O17: =140-90/O9 -> 138.08511
I18: r_e_min | J18: =0.008*J12*(J9^2+180) -> 19.0624 | N18: r_e_min | O18: =0.008*O12*(O9^2+180) -> 162.64312
I19: r_i_max | J19: =0.505*J12+0.069*(J12)^(1/3) -> 4.4384223 | N19: r_i_max | O19: =0.505*O12+0.069*(O12)^(1/3) -> 4.4384223
I20: alpha_min | J20: =120-90/J9 -> 111 | N20: alpha_min | O20: =120-90/O9 -> 118.08511
I21: d_a_max | J21: =J10+1.25*J4-J12 -> 48.463063 | N21: d_a_max | O21: =O10+1.25*O4-O12 -> 197.50573
I22: d_a_min | J22: =J10+J4*(1-1.6/J9)-J12 -> 43.256063 | N22: d_a_min | O22: =O10+O4*(1-1.6/O9)-O12 -> 193.89839
I23: h_a_max | J23: =0.625*J4-0.5*J12+0.8*J4/J9 -> 4.6985 | N23: h_a_max | O23: =0.625*O4-0.5*O12+0.8*O4/O9 -> 3.8986702
I24: h_a_min | J24: =0.5*(J4-J12) -> 2.095 | N24: h_a_min | O24: =0.5*(O4-O12) -> 2.095
I25: angle of pressure [gamma] (deg) | J25: 23.4318 | K25: *from CAD, "Gear Alignment Assembly" | N25: angle of pressure [gamma] (deg) | O25: 32.3689 | P25: *from CAD, "Gear Alignment Assembly"
I26: Tooth Profile | N26: Tooth Profile
I27: h_1 | J27: 12 | K27: *standard to 428 chain | N27: h_1 | O27: 12 | P27: *standard to 428 chain
I28: b_1 (mm) | J28: 7.85 | K28: * plate to plate width of chain | N28: b_1 (mm) | O28: 7.85
I29: bf_1 | J29: =0.93*J28 -> 7.3005 | K29: *with tolerance h14, b_z in CALCULATIONS | N29: bf_1 | O29: =0.93*O28 -> 7.3005 | P29: *with tolerance h14, b_z in CALCULATIONS
I30: bf_2 | J30: =J29 -> 7.3005 | N30: bf_2 | O30: =O29 -> 7.3005
I31: r_x_nom | J31: =J4 -> 12.7 | N31: r_x_nom | O31: =O4 -> 12.7
I32: b_a_nom | J32: =0.13*J4 -> 1.651 | N32: b_a_nom | O32: =0.13*O4 -> 1.651
I33: d_g | J33: =J4*_xlfn.COT(RADIANS(180/J9))-1.04*12-0.76 -> 25.846581 | N33: d_g | O33: =O4*_xlfn.COT(RADIANS(180/O9))-1.04*12-0.76 -> 176.47612
I34: d_f | J34: =J13 -> 32.588063 | N34: d_f | O34: =O13 -> 181.63073
I35: radial runnout | J35: =0.0008*J13+0.08 -> 0.10607045 | N35: radial runnout | O35: =0.0008*O13+0.08 -> 0.22530458
I36: axial runnout | J36: =0.0009*J34+0.08 -> 0.10932926
I38: *goal: use less links than last year to reduce weight
I39: WEIGHT ANALYSIS | J39: *value from CAD | L39: *must be even to fit geartrain
I40: Angle of Wrap (Small Sprocket) | J40: Center to Center Distance Approx. | K40: Exact No. Links | L40: Round No. Links | M40: Weight | N40: Weight AER26 (Datasheet) (66 links) | O40: Weight Difference (kg) | P40: Weight Drop | Q40: Weight AER 26 (Measured?) (67 links) | R40: Weight Difference (kg) | S40: Weight Drop
I41: 120 | J41: 149.04266 | K41: =(2*J41)/$J$4+($J$9+$O$9)/2+($O$9-$J$9)^2*$J$4/(4*PI()*J41) -> 61.25425 | L41: =ROUNDUP(K41,0) -> 62 | M41: =L41*'CHAIN SELECTION'!$C$27 -> 0.62 | N41: =1.2/100*66 -> 0.792 | O41: =N41-M41 -> 0.172 | P41: =(N41-M41)/N41 -> 0.21717172 | Q41: 0.66342614 | R41: =Q41-M41 -> 0.043426144 | S41: =(Q41-M41)/Q41 -> 0.06545739
...

Sheet CALCULATIONS
B1: Operating Speed | C1: HIGH | D1: MEDIUM | E1: LOW
B3: KINEMATICS & CHORDAL ACTION
B5: Gear Ratio [i] | C5: =ASSUMPTIONS!C8/ASSUMPTIONS!C7 -> 4.7 | D5: =ASSUMPTIONS!D8/ASSUMPTIONS!D7 -> 4.7 | E5: =ASSUMPTIONS!E8/ASSUMPTIONS!E7 -> 4.7 | G5: speed reduction or step-up ratio between the small drive sprocket and the large driven sprocket
B6: Angular Velocity Small Sprocket [ω_1] (rad/s) | C6: =(2*PI()*ASSUMPTIONS!C5)/60 -> 620.4 | D6: =(2*PI()*ASSUMPTIONS!D5)/60 -> 310.2 | E6: =(2*PI()*ASSUMPTIONS!E5)/60 -> 155.1 | G6: Converts the motor's rotational speed from revolutions per minute into angular velocity in radians per second
B7: Angular Velocity Large Sprocket [ω_2] (rad/s) | C7: =(2*PI()*ASSUMPTIONS!C6)/60 -> 132 | D7: =(2*PI()*ASSUMPTIONS!D6)/60 -> 66 | E7: =(2*PI()*ASSUMPTIONS!E6)/60 -> 33
B8: Pitch Circle Diameter Small Sprocket [d_1] (mm) | C8: ='CHAIN SELECTION'!C23 / SIN(RADIANS(180 / ASSUMPTIONS!C7)) -> 41.098063 | D8: ='CHAIN SELECTION'!D23 / SIN(RADIANS(180 / ASSUMPTIONS!D7)) -> 41.098063 | E8: ='CHAIN SELECTION'!E23 / SIN(RADIANS(180 / ASSUMPTIONS!E7)) -> 41.098063
B9: Pitch Circle Diameter Large Sprocket [d_2] (mm) | C9: ='CHAIN SELECTION'!C23 / SIN(RADIANS(180 / ASSUMPTIONS!C8)) -> 190.14073 | D9: ='CHAIN SELECTION'!D23 / SIN(RADIANS(180 / ASSUMPTIONS!D8)) -> 190.14073 | E9: ='CHAIN SELECTION'!E23 / SIN(RADIANS(180 / ASSUMPTIONS!E8)) -> 190.14073
A10: SMALL SPROCKET | B10: Small Chain Velocity [v] (m/s) | C10: =('SPROCKET GEOMETRY'!$J$9*'SPROCKET GEOMETRY'!$J$4*0.0393701*ASSUMPTIONS!C5/12)*0.00508 -> 12.539952 | D10: =('SPROCKET GEOMETRY'!$J$9*'SPROCKET GEOMETRY'!$J$4*0.0393701*ASSUMPTIONS!D5/12)*0.00508 -> 6.269976 | E10: =('SPROCKET GEOMETRY'!$J$9*'SPROCKET GEOMETRY'!$J$4*0.0393701*ASSUMPTIONS!E5/12)*0.00508 -> 3.134988 | G10: *this eq. is in feet/min
B11: Small Chain Velocity Min [v_min] (m/s) | C11: ='SPROCKET GEOMETRY'!$J$4*ASSUMPTIONS!C5/(19100*TAN(RADIANS(180/'SPROCKET GEOMETRY'!$J$9))) -> 12.123764 | D11: ='SPROCKET GEOMETRY'!$J$4*ASSUMPTIONS!D5/(19100*TAN(RADIANS(180/'SPROCKET GEOMETRY'!$J$9))) -> 6.0618822 | E11: ='SPROCKET GEOMETRY'!$J$4*ASSUMPTIONS!E5/(19100*TAN(RADIANS(180/'SPROCKET GEOMETRY'!$J$9))) -> 3.0309411 | G11: * this is in m/s, from IWIS
B12: Small Chain Velocity Max [v_max] (m/s) | C12: ='SPROCKET GEOMETRY'!$J$4*ASSUMPTIONS!C5/(19100*SIN(RADIANS(180/'SPROCKET GEOMETRY'!$J$9))) -> 12.74768 | D12: ='SPROCKET GEOMETRY'!$J$4*ASSUMPTIONS!D5/(19100*SIN(RADIANS(180/'SPROCKET GEOMETRY'!$J$9))) -> 6.3738401 | E12: ='SPROCKET GEOMETRY'!$J$4*ASSUMPTIONS!E5/(19100*SIN(RADIANS(180/'SPROCKET GEOMETRY'!$J$9))) -> 3.1869201
B13: Small Speed Variation [δ] | C13: =(C12-C11)/C10 -> 0.049754248 | D13: =(D12-D11)/D10 -> 0.049754248 | E13: =(E12-E11)/E10 -> 0.049754248
A14: LARGE SPROCKET | B14: Large Chain Velocity [v] (m/s) | C14: =('SPROCKET GEOMETRY'!$O$9*'SPROCKET GEOMETRY'!$O$4*0.0393701*ASSUMPTIONS!C6/12)*0.00508 -> 12.539952 | D14: =('SPROCKET GEOMETRY'!$O$9*'SPROCKET GEOMETRY'!$O$4*0.0393701*ASSUMPTIONS!D6/12)*0.00508 -> 6.269976 | E14: =('SPROCKET GEOMETRY'!$O$9*'SPROCKET GEOMETRY'!$O$4*0.0393701*ASSUMPTIONS!E6/12)*0.00508 -> 3.134988 | G14: *this eq. is in feet/min
B15: Large Chain Velocity Min [v_min] (m/s) | C15: ='SPROCKET GEOMETRY'!$O$4*ASSUMPTIONS!C6/(19100*TAN(RADIANS(180/'SPROCKET GEOMETRY'!$O$9))) -> 12.520342 | D15: ='SPROCKET GEOMETRY'!$O$4*ASSUMPTIONS!D6/(19100*TAN(RADIANS(180/'SPROCKET GEOMETRY'!$O$9))) -> 6.2601708 | E15: ='SPROCKET GEOMETRY'!$O$4*ASSUMPTIONS!E6/(19100*TAN(RADIANS(180/'SPROCKET GEOMETRY'!$O$9))) -> 3.1300854 | G15: * this is in m/s, from IWIS
B16: Large Chain Velocity Max [v_max] (m/s) | C16: ='SPROCKET GEOMETRY'!$O$4*ASSUMPTIONS!C6/(19100*SIN(RADIANS(180/'SPROCKET GEOMETRY'!$O$9))) -> 12.548364 | D16: ='SPROCKET GEOMETRY'!$O$4*ASSUMPTIONS!D6/(19100*SIN(RADIANS(180/'SPROCKET GEOMETRY'!$O$9))) -> 6.2741819 | E16: ='SPROCKET GEOMETRY'!$O$4*ASSUMPTIONS!E6/(19100*SIN(RADIANS(180/'SPROCKET GEOMETRY'!$O$9))) -> 3.1370909
B17: Large Speed Variation [δ] | C17: =(C16-C15)/C14 -> 0.0022346193 | D17: =(D16-D15)/D14 -> 0.0022346193 | E17: =(E16-E15)/E14 -> 0.0022346193
B19: CHAIN LOAD & POWER
B21: Transmitted Power [P] (W) | C21: =ASSUMPTIONS!C4*ASSUMPTIONS!C5/9550 -> 66.712902 | D21: =ASSUMPTIONS!D4*ASSUMPTIONS!D5/9550 -> 33.356451 | E21: =ASSUMPTIONS!E4*ASSUMPTIONS!E5/9550 -> 16.678225 | G21: *n1 is rpm , comes from P = Torque x Angular Speed
B22: Chain Pull [F] (N) | C22: =2000*ASSUMPTIONS!C4/CALCULATIONS!C8 -> 5233.3366 | D22: =2000*ASSUMPTIONS!D4/CALCULATIONS!D8 -> 5233.3366 | E22: =2000*ASSUMPTIONS!E4/CALCULATIONS!E8 -> 5233.3366 | G22: * tangential force, comes from M= F x d, max force found at small sprocket
B23: Centrifugal Force [ F_f] (N) | C23: ='CHAIN SELECTION'!C26*CALCULATIONS!C10^2 -> 123.81921 | D23: ='CHAIN SELECTION'!D26*CALCULATIONS!D10^2 -> 30.954803 | E23: ='CHAIN SELECTION'!E26*CALCULATIONS!E10^2 -> 7.7387007 | G23: * comes from F = mV^2/r, same velocity for both sprockets
B24: Total Working Tension [F_t] (N) | C24: =C22+C23 -> 5357.1558 | D24: =D22+D23 -> 5264.2914 | E24: =E22+E23 -> 5241.0753
B26: DYAMIC IMPACT & STRESS ANALYSIS | C26: * Impact is the roller hitting the sprocket when it engages
B28: Total Working Tension [F_t] (N) | C28: =C24 -> 5357.1558 | D28: =D24 -> 5264.2914 | E28: =E24 -> 5241.0753
B29: Small Sprocket Pressure Angle [γ] | C29: ='SPROCKET GEOMETRY'!J25 -> 23.4318 | D29: =C29 -> 23.4318 | E29: =D29 -> 23.4318
B30: Large Sprocket Pressure Angle [γ] | C30: ='SPROCKET GEOMETRY'!O25 -> 32.3689 | D30: =C30 -> 32.3689 | E30: =D30 -> 32.3689
A31: SMALL SPROCKET | B31: Small Impact Velocity [v_A] (m/s) | C31: =(PI()*ASSUMPTIONS!C5*'SPROCKET GEOMETRY'!$J$4/30000)*SIN(RADIANS(360/'SPROCKET GEOMETRY'!$J$9+CALCULATIONS!C29)) -> 6.7840803 | D31: =(PI()*ASSUMPTIONS!D5*'SPROCKET GEOMETRY'!$J$4/30000)*SIN(RADIANS(360/'SPROCKET GEOMETRY'!$J$9+CALCULATIONS!D29)) -> 3.3920401 | E31: =(PI()*ASSUMPTIONS!E5*'SPROCKET GEOMETRY'!$J$4/30000)*SIN(RADIANS(360/'SPROCKET GEOMETRY'!$J$9+CALCULATIONS!E29)) -> 1.6960201 | J31: *LARGER FORCES ACTING ON SMALL SPROCKET
B32: Small Roller Impact Energy [E_A] (J) | C32: =('CHAIN SELECTION'!C26*'CHAIN SELECTION'!C23/2000)*C31^2 -> 0.23011873 | D32: =('CHAIN SELECTION'!D26*'CHAIN SELECTION'!D23/2000)*D31^2 -> 0.057529682 | E32: =('CHAIN SELECTION'!E26*'CHAIN SELECTION'!E23/2000)*E31^2 -> 0.01438242 | J32: *energy absorbed by roller
B33: Small Dynamic Impact Force [F_A] (N) | C33: =SQRT('CHAIN SELECTION'!C26*'SPROCKET GEOMETRY'!$J$4*'SPROCKET GEOMETRY'!$J$29*'CHAIN SELECTION'!C28/3)*CALCULATIONS!C31 -> 14966.548 | D33: =SQRT('CHAIN SELECTION'!D26*'SPROCKET GEOMETRY'!$J$4*'SPROCKET GEOMETRY'!$J$29*'CHAIN SELECTION'!D28/3)*CALCULATIONS!D31 -> 7483.2742 | E33: =SQRT('CHAIN SELECTION'!E26*'SPROCKET GEOMETRY'!$J$4*'SPROCKET GEOMETRY'!$J$29*'CHAIN SELECTION'!E28/3)*CALCULATIONS!E31 -> 3741.6371
A34: LARGE SPROCKET | B34: Large Impact Velocity [v_A] | C34: =(PI()*ASSUMPTIONS!C6*'SPROCKET GEOMETRY'!$O$4/30000)*SIN(RADIANS(360/'SPROCKET GEOMETRY'!$O$9+CALCULATIONS!C30)) -> 1.0782072 | D34: =(PI()*ASSUMPTIONS!D6*'SPROCKET GEOMETRY'!$O$4/30000)*SIN(RADIANS(360/'SPROCKET GEOMETRY'!$O$9+CALCULATIONS!D30)) -> 0.53910361 | E34: =(PI()*ASSUMPTIONS!E6*'SPROCKET GEOMETRY'!$O$4/30000)*SIN(RADIANS(360/'SPROCKET GEOMETRY'!$O$9+CALCULATIONS!E30)) -> 0.26955181
B35: Large Roller Impact Energy [E_A] | C35: =('CHAIN SELECTION'!C26*'CHAIN SELECTION'!C23/2000)*C34^2 -> 0.0058126541 | D35: =('CHAIN SELECTION'!D26*'CHAIN SELECTION'!D23/2000)*D34^2 -> 0.0014531635 | E35: =('CHAIN SELECTION'!E26*'CHAIN SELECTION'!E23/2000)*E34^2 -> 0.00036329088
B36: Large Dynamic Impact Force [F_A] | C36: =SQRT('CHAIN SELECTION'!C26*'SPROCKET GEOMETRY'!$O$4*'SPROCKET GEOMETRY'!$O$29*'CHAIN SELECTION'!C28/3)*CALCULATIONS!C34 -> 2378.663 | D36: =SQRT('CHAIN SELECTION'!D26*'SPROCKET GEOMETRY'!$O$4*'SPROCKET GEOMETRY'!$O$29*'CHAIN SELECTION'!D28/3)*CALCULATIONS!D34 -> 1189.3315 | E36: =SQRT('CHAIN SELECTION'!E26*'SPROCKET GEOMETRY'!$O$4*'SPROCKET GEOMETRY'!$O$29*'CHAIN SELECTION'!E28/3)*CALCULATIONS!E34 -> 594.66574
B38: TOOTH STRESS
B40: 10T Impact Area (m^2) | C40: =23.61/1000000 -> 2.361e-05 | D40: =23.61/1000000 -> 2.361e-05 | E40: =23.61/1000000 -> 2.361e-05 | F40: *23.61 mm^2
B41: 10T Impact Stress (Pa) | C41: =C33/C40 -> 6.3390717e+08 | D41: =D33/D40 -> 3.1695359e+08 | E41: =E33/E40 -> 1.5847679e+08
B42: 47T Impact Area (m^2) | C42: =27.66/1000000 -> 2.766e-05 | D42: =27.66/1000000 -> 2.766e-05 | E42: =27.66/1000000 -> 2.766e-05 | F42: *27.66 mm^2, area bounded by two boxes (pictured)
B43: 47T Impact Stress (Pa) | C43: =C36/C42 -> 85996492 | D43: =D36/D42 -> 42998246 | E43: =E36/E42 -> 21499123

Sheet FEA LOAD CALCULATIONS
A1: REFERENCE:http://chain-guide.com/basics/2-1-2-engagement-with-sprockets.html
B2: Operating Speed | C2: HIGH | D2: MEDIUM | E2: LOW | G2: Operating Speed | H2: HIGH | I2: MEDIUM | J2: LOW
B4: SMALL SPROCKET | G4: LARGE SPROCKET | N4: *Only works for driven sprocket
B5: Chain Tension (N) | C5: =CALCULATIONS!C28 -> 5357.1558 | D5: =CALCULATIONS!D28 -> 5264.2914 | E5: =CALCULATIONS!E28 -> 5241.0753 | G5: Chain Tension (N) | H5: =CALCULATIONS!C28 -> 5357.1558 | I5: =CALCULATIONS!D28 -> 5264.2914 | J5: =CALCULATIONS!E28 -> 5241.0753
B6: θ | C6: =17-64/C7 -> 10.6 | D6: =17-64/D7 -> 10.6 | E6: =17-64/E7 -> 10.6 | G6: θ | H6: =17-64/H7 -> 15.638298 | I6: =17-64/I7 -> 15.638298 | J6: =17-64/J7 -> 15.638298
B7: Number Teeth | C7: ='SPROCKET GEOMETRY'!J9 -> 10 | D7: =C7 -> 10 | E7: =D7 -> 10 | G7: Number Teeth | H7: ='SPROCKET GEOMETRY'!O9 -> 47 | I7: =H7 -> 47 | J7: =I7 -> 47
B8: 2β | C8: =360/C7 -> 36 | D8: =360/D7 -> 36 | E8: =360/E7 -> 36 | G8: 2β | H8: =360/H7 -> 7.6595745 | I8: =360/I7 -> 7.6595745 | J8: =360/J7 -> 7.6595745
B9: k | C9: =ROUNDDOWN('SPROCKET GEOMETRY'!$J$57*'FEA LOAD CALCULATIONS'!C7/360,0) -> 3 | D9: =ROUNDDOWN('SPROCKET GEOMETRY'!$J$57*'FEA LOAD CALCULATIONS'!D7/360,0) -> 3 | E9: =ROUNDDOWN('SPROCKET GEOMETRY'!$J$57*'FEA LOAD CALCULATIONS'!E7/360,0) -> 3 | G9: k | H9: =ROUNDDOWN('SPROCKET GEOMETRY'!$L$57*'FEA LOAD CALCULATIONS'!H7/360,0) -> 28 | I9: =ROUNDDOWN('SPROCKET GEOMETRY'!$L$57*'FEA LOAD CALCULATIONS'!I7/360,0) -> 28 | J9: =ROUNDDOWN('SPROCKET GEOMETRY'!$L$57*'FEA LOAD CALCULATIONS'!J7/360,0) -> 28
B11: k | C11: Tension | D11: Tension | E11: Tension | G11: k | H11: Back Tension | I11: Back Tension | J11: Back Tension
B12: 1 | C12: =C5/3 -> 1785.7186 | D12: =D5/3 -> 1754.7638 | E12: =E5/3 -> 1747.0251 | G12: 1 | H12: =H5 -> 5357.1558 | I12: =CALCULATIONS!D36 -> 1189.3315 | J12: =CALCULATIONS!E36 -> 594.66574 | K12: =0.19/2*H12 -> 508.9298
B13: 2 | C13: =CALCULATIONS!C28/3 -> 1785.7186 | D13: =CALCULATIONS!D28/3 -> 1754.7638 | E13: =CALCULATIONS!E28/3 -> 1747.0251 | F13: *F total /3 (even across each tooth) | G13: 2 | H13: =H5*(SIN(RADIANS(H6))/SIN(RADIANS(H6+H8)))^G13-1 -> 2487.5057 | I13: =I5*(SIN(RADIANS(I6))/SIN(RADIANS(I6+I8)))^G13-1 -> 2444.3684 | J13: =J5*(SIN(RADIANS(J6))/SIN(RADIANS(J6+J8)))^G13-1 -> 2433.584 | K13: =0.19/2*H13 -> 236.31305
B14: 3 | C14: =CALCULATIONS!C28/3 -> 1785.7186 | D14: =CALCULATIONS!D28/3 -> 1754.7638 | E14: =CALCULATIONS!E28/3 -> 1747.0251 | G14: 3 | H14: =H$5*(SIN(RADIANS(H$6))/SIN(RADIANS(H$6+H$8)))^$G14-1 -> 1695.0585 | I14: =I$5*(SIN(RADIANS(I$6))/SIN(RADIANS(I$6+I$8)))^$G14-1 -> 1665.6579 | J14: =J$5*(SIN(RADIANS(J$6))/SIN(RADIANS(J$6+J$8)))^$G14-1 -> 1658.3078 | K14: =0.19/2*H14 -> 161.03056
G15: 4 | H15: =H$5*(SIN(RADIANS(H$6))/SIN(RADIANS(H$6+H$8)))^$G15-1 -> 1154.9606 | I15: =I$5*(SIN(RADIANS(I$6))/SIN(RADIANS(I$6+I$8)))^$G15-1 -> 1134.9224 | J15: =J$5*(SIN(RADIANS(J$6))/SIN(RADIANS(J$6+J$8)))^$G15-1 -> 1129.9128 | K15: =0.19/2*H15 -> 109.72125
G16: 5 | H16: =H$5*(SIN(RADIANS(H$6))/SIN(RADIANS(H$6+H$8)))^$G16-1 -> 786.85301 | I16: =I$5*(SIN(RADIANS(I$6))/SIN(RADIANS(I$6+I$8)))^$G16-1 -> 773.19586 | J16: =J$5*(SIN(RADIANS(J$6))/SIN(RADIANS(J$6+J$8)))^$G16-1 -> 769.78157 | K16: =0.19/2*H16 -> 74.751036
G17: 6 | H17: =H$5*(SIN(RADIANS(H$6))/SIN(RADIANS(H$6+H$8)))^$G17-1 -> 535.96674 | I17: =I$5*(SIN(RADIANS(I$6))/SIN(RADIANS(I$6+I$8)))^$G17-1 -> 526.65861 | J17: =J$5*(SIN(RADIANS(J$6))/SIN(RADIANS(J$6+J$8)))^$G17-1 -> 524.33158 | K17: =0.19/2*H17 -> 50.91684 | M17: SF | N17: Maximum Moment
G18: 7 | H18: =H$5*(SIN(RADIANS(H$6))/SIN(RADIANS(H$6+H$8)))^$G18-1 -> 364.97344 | I18: =I$5*(SIN(RADIANS(I$6))/SIN(RADIANS(I$6+I$8)))^$G18-1 -> 358.62942 | J18: =J$5*(SIN(RADIANS(J$6))/SIN(RADIANS(J$6+J$8)))^$G18-1 -> 357.04341 | K18: =0.19/2*H18 -> 34.672477 | M18: 1 | N18: =H5*'SPROCKET GEOMETRY'!O21/2000 -> 529.03448
G19: 8 | H19: =H$5*(SIN(RADIANS(H$6))/SIN(RADIANS(H$6+H$8)))^$G19-1 -> 248.43176 | I19: =I$5*(SIN(RADIANS(I$6))/SIN(RADIANS(I$6+I$8)))^$G19-1 -> 244.10795 | J19: =J$5*(SIN(RADIANS(J$6))/SIN(RADIANS(J$6+J$8)))^$G19-1 -> 243.027 | K19: =0.19/2*H19 -> 23.601017 | M19: 2 | N19: =N18*M19 -> 1058.069
G20: 9 | H20: =H$5*(SIN(RADIANS(H$6))/SIN(RADIANS(H$6+H$8)))^$G20-1 -> 169.00196 | I20: =I$5*(SIN(RADIANS(I$6))/SIN(RADIANS(I$6+I$8)))^$G20-1 -> 166.05504 | J20: =J$5*(SIN(RADIANS(J$6))/SIN(RADIANS(J$6+J$8)))^$G20-1 -> 165.31831 | K20: =0.19/2*H20 -> 16.055186 | M20: 3 | N20: =N18*M20 -> 1587.1034
G21: 10 | H21: =H$5*(SIN(RADIANS(H$6))/SIN(RADIANS(H$6+H$8)))^$G21-1 -> 114.86603 | I21: =I$5*(SIN(RADIANS(I$6))/SIN(RADIANS(I$6+I$8)))^$G21-1 -> 112.85753 | J21: =J$5*(SIN(RADIANS(J$6))/SIN(RADIANS(J$6+J$8)))^$G21-1 -> 112.35541 | K21: =0.19/2*H21 -> 10.912273
G22: 11 | H22: =H$5*(SIN(RADIANS(H$6))/SIN(RADIANS(H$6+H$8)))^$G22-1 -> 77.969303 | I22: =I$5*(SIN(RADIANS(I$6))/SIN(RADIANS(I$6+I$8)))^$G22-1 -> 76.600398 | J22: =J$5*(SIN(RADIANS(J$6))/SIN(RADIANS(J$6+J$8)))^$G22-1 -> 76.258172 | K22: =0.19/2*H22 -> 7.4070838
G23: 12 | H23: =H$5*(SIN(RADIANS(H$6))/SIN(RADIANS(H$6+H$8)))^$G23-1 -> 52.822081 | I23: =I$5*(SIN(RADIANS(I$6))/SIN(RADIANS(I$6+I$8)))^$G23-1 -> 51.889094 | J23: =J$5*(SIN(RADIANS(J$6))/SIN(RADIANS(J$6+J$8)))^$G23-1 -> 51.655848 | K23: =0.19/2*H23 -> 5.0180977
G24: 13 | H24: =H$5*(SIN(RADIANS(H$6))/SIN(RADIANS(H$6+H$8)))^$G24-1 -> 35.682816 | I24: =I$5*(SIN(RADIANS(I$6))/SIN(RADIANS(I$6+I$8)))^$G24-1 -> 35.046933 | J24: =J$5*(SIN(RADIANS(J$6))/SIN(RADIANS(J$6+J$8)))^$G24-1 -> 34.887962 | K24: =0.19/2*H24 -> 3.3898676
G25: 14 | H25: =H$5*(SIN(RADIANS(H$6))/SIN(RADIANS(H$6+H$8)))^$G25-1 -> 24.00143 | I25: =I$5*(SIN(RADIANS(I$6))/SIN(RADIANS(I$6+I$8)))^$G25-1 -> 23.568039 | J25: =J$5*(SIN(RADIANS(J$6))/SIN(RADIANS(J$6+J$8)))^$G25-1 -> 23.459692 | K25: =0.19/2*H25 -> 2.2801359
G26: 15 | H26: =H$5*(SIN(RADIANS(H$6))/SIN(RADIANS(H$6+H$8)))^$G26-1 -> 16.0399 | I26: =I$5*(SIN(RADIANS(I$6))/SIN(RADIANS(I$6+I$8)))^$G26-1 -> 15.744519 | J26: =J$5*(SIN(RADIANS(J$6))/SIN(RADIANS(J$6+J$8)))^$G26-1 -> 15.670674 | K26: =0.19/2*H26 -> 1.5237905
G27: 16 | H27: =H$5*(SIN(RADIANS(H$6))/SIN(RADIANS(H$6+H$8)))^$G27-1 -> 10.613663 | I27: =I$5*(SIN(RADIANS(I$6))/SIN(RADIANS(I$6+I$8)))^$G27-1 -> 10.412344 | J27: =J$5*(SIN(RADIANS(J$6))/SIN(RADIANS(J$6+J$8)))^$G27-1 -> 10.362015 | K27: =0.19/2*H27 -> 1.008298
G28: 17 | H28: =H$5*(SIN(RADIANS(H$6))/SIN(RADIANS(H$6+H$8)))^$G28-1 -> 6.9153734 | I28: =I$5*(SIN(RADIANS(I$6))/SIN(RADIANS(I$6+I$8)))^$G28-1 -> 6.7781632 | J28: =J$5*(SIN(RADIANS(J$6))/SIN(RADIANS(J$6+J$8)))^$G28-1 -> 6.7438607 | K28: =0.19/2*H28 -> 0.65696047
G29: 18 | H29: =H$5*(SIN(RADIANS(H$6))/SIN(RADIANS(H$6+H$8)))^$G29-1 -> 4.3947782 | I29: =I$5*(SIN(RADIANS(I$6))/SIN(RADIANS(I$6+I$8)))^$G29-1 -> 4.3012616 | J29: =J$5*(SIN(RADIANS(J$6))/SIN(RADIANS(J$6+J$8)))^$G29-1 -> 4.2778825 | K29: =0.19/2*H29 -> 0.41750393
G30: 19 | H30: =H$5*(SIN(RADIANS(H$6))/SIN(RADIANS(H$6+H$8)))^$G30-1 -> 2.6768488 | I30: =I$5*(SIN(RADIANS(I$6))/SIN(RADIANS(I$6+I$8)))^$G30-1 -> 2.613112 | J30: =J$5*(SIN(RADIANS(J$6))/SIN(RADIANS(J$6+J$8)))^$G30-1 -> 2.5971777 | K30: =0.19/2*H30 -> 0.25430064
G31: 20 | H31: =H$5*(SIN(RADIANS(H$6))/SIN(RADIANS(H$6+H$8)))^$G31-1 -> 1.5059821 | I31: =I$5*(SIN(RADIANS(I$6))/SIN(RADIANS(I$6+I$8)))^$G31-1 -> 1.4625418 | J31: =J$5*(SIN(RADIANS(J$6))/SIN(RADIANS(J$6+J$8)))^$G31-1 -> 1.4516817 | K31: =0.19/2*H31 -> 0.1430683
G32: 21 | H32: =H$5*(SIN(RADIANS(H$6))/SIN(RADIANS(H$6+H$8)))^$G32-1 -> 0.70796963 | I32: =I$5*(SIN(RADIANS(I$6))/SIN(RADIANS(I$6+I$8)))^$G32-1 -> 0.67836258 | J32: =J$5*(SIN(RADIANS(J$6))/SIN(RADIANS(J$6+J$8)))^$G32-1 -> 0.67096081 | K32: =0.19/2*H32 -> 0.067257115
G33: 22 | H33: =H$5*(SIN(RADIANS(H$6))/SIN(RADIANS(H$6+H$8)))^$G33-1 -> 0.16407866 | I33: =I$5*(SIN(RADIANS(I$6))/SIN(RADIANS(I$6+I$8)))^$G33-1 -> 0.14389977 | J33: =J$5*(SIN(RADIANS(J$6))/SIN(RADIANS(J$6+J$8)))^$G33-1 -> 0.13885504 | K33: =0.19/2*H33 -> 0.015587473
G34: 23 | H34: =H$5*(SIN(RADIANS(H$6))/SIN(RADIANS(H$6+H$8)))^$G34-1 -> -0.20661404 | I34: =I$5*(SIN(RADIANS(I$6))/SIN(RADIANS(I$6+I$8)))^$G34-1 -> -0.2203671 | J34: =J$5*(SIN(RADIANS(J$6))/SIN(RADIANS(J$6+J$8)))^$G34-1 -> -0.22380537
G35: 24 | H35: =H$5*(SIN(RADIANS(H$6))/SIN(RADIANS(H$6+H$8)))^$G35-1 -> -0.45926224 | I35: =I$5*(SIN(RADIANS(I$6))/SIN(RADIANS(I$6+I$8)))^$G35-1 -> -0.46863574 | J35: =J$5*(SIN(RADIANS(J$6))/SIN(RADIANS(J$6+J$8)))^$G35-1 -> -0.47097912
G36: 25 | H36: =H$5*(SIN(RADIANS(H$6))/SIN(RADIANS(H$6+H$8)))^$G36-1 -> -0.63145639 | I36: =I$5*(SIN(RADIANS(I$6))/SIN(RADIANS(I$6+I$8)))^$G36-1 -> -0.63784497 | J36: =J$5*(SIN(RADIANS(J$6))/SIN(RADIANS(J$6+J$8)))^$G36-1 -> -0.63944211
G37: 26 | H37: =H$5*(SIN(RADIANS(H$6))/SIN(RADIANS(H$6+H$8)))^$G37-1 -> -0.74881653 | I37: =I$5*(SIN(RADIANS(I$6))/SIN(RADIANS(I$6+I$8)))^$G37-1 -> -0.7531707 | J37: =J$5*(SIN(RADIANS(J$6))/SIN(RADIANS(J$6+J$8)))^$G37-1 -> -0.75425925
G38: 27 | H38: =H$5*(SIN(RADIANS(H$6))/SIN(RADIANS(H$6+H$8)))^$G38-1 -> -0.82880414 | I38: =I$5*(SIN(RADIANS(I$6))/SIN(RADIANS(I$6+I$8)))^$G38-1 -> -0.83177176 | J38: =J$5*(SIN(RADIANS(J$6))/SIN(RADIANS(J$6+J$8)))^$G38-1 -> -0.83251367
G39: 28 | H39: =H$5*(SIN(RADIANS(H$6))/SIN(RADIANS(H$6+H$8)))^$G39-1 -> -0.88332027 | I39: =I$5*(SIN(RADIANS(I$6))/SIN(RADIANS(I$6+I$8)))^$G39-1 -> -0.88534287 | J39: =J$5*(SIN(RADIANS(J$6))/SIN(RADIANS(J$6+J$8)))^$G39-1 -> -0.88584852

Sheet FEA DOCUMENTATION
B2: 47 T Sprocket & Hub
B4: 3mm mesh
B7: GETTING RID OF MARGINAL | O7: GETTING RID OF MARGINAL
AW10: APPLYING 2X MAXIMUM MOMENT | BE10: APPLYING 3X MAXIMUM MOMENT
B33: 10% LESS MATERIAL THAN MARGINAL | O33: 10% LESS MATERIAL THAN MARGINAL
B60: ORIGINAL | O60: ORIGINAL
B87: OPTIMIZATION 1 | O87: OPTIMIZATION 1

Sheet MASS TARGETS
C1: *CAD ESTIMATE | E1: *CAD ESTIMATE | F1: *CAD | G1: *CAD
C2: AER 26 | D2: AER 26 | E2: AER27 | F2: MASS REDUCTION | G2: % REDUCTION
B3: 47T Sprocket | C3: 1.886 | D3: 0.688 | E3: 0.608 | F3: =C3-E3 -> 1.278 | G3: =(C3-E3)/C3 -> 0.6776246
B4: 47T Sprocket Hub | C4: 0.267 | D4: 0.228 | E4: 0.305 | F4: =C4-E4 -> -0.038 | G4: =(C4-E4)/C4 -> -0.1423221
A5: *27' INCLUDES DRIVESHAFT | B5: 10T Sprokcet | C5: 0.075 | E5: 0.16 | F5: =C5-E5 -> -0.085 | G5: =(C5-E5)/C5 -> -1.1333333
B6: 10T Sprokcet Hub | C6: 0.203 | E6: 0.09 | F6: =C6-E6 -> 0.113 | G6: =(C6-E6)/C6 -> 0.55665025
B7: Driveshaft | C7: 0.099 | E7: 0 | F7: =C7-E7 -> 0.099 | G7: =(C7-E7)/C7 -> 1
B8: TOTAL | C8: =SUM(C3:C7) -> 2.53 | E8: =SUM(E3:E7) -> 1.163 | F8: =SUM(F3:F7) -> 1.367 | G8: =(C8-E8)/C8 -> 0.54031621
B9: GOAL | C9: =C8-0.1*C8 -> 2.277
B10: TOTAL MASS REDUCTION | C10: =C8-E8 -> 1.367

Sheet BOLT SHEAR CALCULATION
